[2024-09-17T23:26:14.177+0000] {local_task_job_runner.py:123} INFO - ::group::Pre task execution logs
[2024-09-17T23:26:14.409+0000] {taskinstance.py:2612} INFO - Dependencies all met for dep_context=non-requeueable deps ti=<TaskInstance: Bitcoin_ETL.extraer_data manual__2024-09-17T23:16:03.683913+00:00 [queued]>
[2024-09-17T23:26:14.419+0000] {taskinstance.py:2612} INFO - Dependencies all met for dep_context=requeueable deps ti=<TaskInstance: Bitcoin_ETL.extraer_data manual__2024-09-17T23:16:03.683913+00:00 [queued]>
[2024-09-17T23:26:14.420+0000] {taskinstance.py:2865} INFO - Starting attempt 3 of 6
[2024-09-17T23:26:14.435+0000] {taskinstance.py:2888} INFO - Executing <Task(PythonOperator): extraer_data> on 2024-09-17 23:16:03.683913+00:00
[2024-09-17T23:26:14.444+0000] {warnings.py:112} WARNING - /home/***/.local/lib/python3.12/site-packages/***/task/task_runner/standard_task_runner.py:70: DeprecationWarning: This process (pid=231) is multi-threaded, use of fork() may lead to deadlocks in the child.
  pid = os.fork()

[2024-09-17T23:26:14.447+0000] {standard_task_runner.py:72} INFO - Started process 235 to run task
[2024-09-17T23:26:14.447+0000] {standard_task_runner.py:104} INFO - Running: ['***', 'tasks', 'run', 'Bitcoin_ETL', 'extraer_data', 'manual__2024-09-17T23:16:03.683913+00:00', '--job-id', '37', '--raw', '--subdir', 'DAGS_FOLDER/API_Crypto_Extraction.py', '--cfg-path', '/tmp/tmprwtsyktf']
[2024-09-17T23:26:14.451+0000] {standard_task_runner.py:105} INFO - Job 37: Subtask extraer_data
[2024-09-17T23:26:14.513+0000] {task_command.py:467} INFO - Running <TaskInstance: Bitcoin_ETL.extraer_data manual__2024-09-17T23:16:03.683913+00:00 [running]> on host 868230e8e335
[2024-09-17T23:26:14.619+0000] {taskinstance.py:3131} INFO - Exporting env vars: AIRFLOW_CTX_DAG_OWNER='NicolasRivas' AIRFLOW_CTX_DAG_ID='Bitcoin_ETL' AIRFLOW_CTX_TASK_ID='extraer_data' AIRFLOW_CTX_EXECUTION_DATE='2024-09-17T23:16:03.683913+00:00' AIRFLOW_CTX_TRY_NUMBER='3' AIRFLOW_CTX_DAG_RUN_ID='manual__2024-09-17T23:16:03.683913+00:00'
[2024-09-17T23:26:14.622+0000] {taskinstance.py:731} INFO - ::endgroup::
[2024-09-17T23:26:16.016+0000] {taskinstance.py:3310} ERROR - Task failed with exception
Traceback (most recent call last):
  File "/home/airflow/.local/lib/python3.12/site-packages/airflow/models/taskinstance.py", line 767, in _execute_task
    result = _execute_callable(context=context, **execute_callable_kwargs)
             ^^^^^^^^^^^^^^^^^^^^^^^^^^^^^^^^^^^^^^^^^^^^^^^^^^^^^^^^^^^^^
  File "/home/airflow/.local/lib/python3.12/site-packages/airflow/models/taskinstance.py", line 733, in _execute_callable
    return ExecutionCallableRunner(
           ^^^^^^^^^^^^^^^^^^^^^^^^
  File "/home/airflow/.local/lib/python3.12/site-packages/airflow/utils/operator_helpers.py", line 252, in run
    return self.func(*args, **kwargs)
           ^^^^^^^^^^^^^^^^^^^^^^^^^^
  File "/home/airflow/.local/lib/python3.12/site-packages/airflow/models/baseoperator.py", line 406, in wrapper
    return func(self, *args, **kwargs)
           ^^^^^^^^^^^^^^^^^^^^^^^^^^^
  File "/home/airflow/.local/lib/python3.12/site-packages/airflow/operators/python.py", line 238, in execute
    return_value = self.execute_callable()
                   ^^^^^^^^^^^^^^^^^^^^^^^
  File "/home/airflow/.local/lib/python3.12/site-packages/airflow/operators/python.py", line 256, in execute_callable
    return runner.run(*self.op_args, **self.op_kwargs)
           ^^^^^^^^^^^^^^^^^^^^^^^^^^^^^^^^^^^^^^^^^^^
  File "/home/airflow/.local/lib/python3.12/site-packages/airflow/utils/operator_helpers.py", line 252, in run
    return self.func(*args, **kwargs)
           ^^^^^^^^^^^^^^^^^^^^^^^^^^
  File "/opt/airflow/dags/API_Crypto_Extraction.py", line 46, in cargar_data_a_base
    print(f"df final es {df_final.columns()}")
                         ^^^^^^^^^^^^^^^^^^
TypeError: 'Index' object is not callable
[2024-09-17T23:26:16.035+0000] {taskinstance.py:1225} INFO - Marking task as UP_FOR_RETRY. dag_id=Bitcoin_ETL, task_id=extraer_data, run_id=manual__2024-09-17T23:16:03.683913+00:00, execution_date=20240917T231603, start_date=20240917T232614, end_date=20240917T232616
[2024-09-17T23:26:16.055+0000] {taskinstance.py:340} INFO - ::group::Post task execution logs
[2024-09-17T23:26:16.056+0000] {standard_task_runner.py:124} ERROR - Failed to execute job 37 for task extraer_data ('Index' object is not callable; 235)
Traceback (most recent call last):
  File "/home/airflow/.local/lib/python3.12/site-packages/airflow/task/task_runner/standard_task_runner.py", line 117, in _start_by_fork
    ret = args.func(args, dag=self.dag)
          ^^^^^^^^^^^^^^^^^^^^^^^^^^^^^
  File "/home/airflow/.local/lib/python3.12/site-packages/airflow/cli/cli_config.py", line 49, in command
    return func(*args, **kwargs)
           ^^^^^^^^^^^^^^^^^^^^^
  File "/home/airflow/.local/lib/python3.12/site-packages/airflow/utils/cli.py", line 115, in wrapper
    return f(*args, **kwargs)
           ^^^^^^^^^^^^^^^^^^
  File "/home/airflow/.local/lib/python3.12/site-packages/airflow/cli/commands/task_command.py", line 483, in task_run
    task_return_code = _run_task_by_selected_method(args, _dag, ti)
                       ^^^^^^^^^^^^^^^^^^^^^^^^^^^^^^^^^^^^^^^^^^^^
  File "/home/airflow/.local/lib/python3.12/site-packages/airflow/cli/commands/task_command.py", line 256, in _run_task_by_selected_method
    return _run_raw_task(args, ti)
           ^^^^^^^^^^^^^^^^^^^^^^^
  File "/home/airflow/.local/lib/python3.12/site-packages/airflow/cli/commands/task_command.py", line 341, in _run_raw_task
    return ti._run_raw_task(
           ^^^^^^^^^^^^^^^^^
  File "/home/airflow/.local/lib/python3.12/site-packages/airflow/utils/session.py", line 97, in wrapper
    return func(*args, session=session, **kwargs)
           ^^^^^^^^^^^^^^^^^^^^^^^^^^^^^^^^^^^^^^
  File "/home/airflow/.local/lib/python3.12/site-packages/airflow/models/taskinstance.py", line 3004, in _run_raw_task
    return _run_raw_task(
           ^^^^^^^^^^^^^^
  File "/home/airflow/.local/lib/python3.12/site-packages/airflow/models/taskinstance.py", line 273, in _run_raw_task
    TaskInstance._execute_task_with_callbacks(
  File "/home/airflow/.local/lib/python3.12/site-packages/airflow/models/taskinstance.py", line 3158, in _execute_task_with_callbacks
    result = self._execute_task(context, task_orig)
             ^^^^^^^^^^^^^^^^^^^^^^^^^^^^^^^^^^^^^^
  File "/home/airflow/.local/lib/python3.12/site-packages/airflow/models/taskinstance.py", line 3182, in _execute_task
    return _execute_task(self, context, task_orig)
           ^^^^^^^^^^^^^^^^^^^^^^^^^^^^^^^^^^^^^^^
  File "/home/airflow/.local/lib/python3.12/site-packages/airflow/models/taskinstance.py", line 767, in _execute_task
    result = _execute_callable(context=context, **execute_callable_kwargs)
             ^^^^^^^^^^^^^^^^^^^^^^^^^^^^^^^^^^^^^^^^^^^^^^^^^^^^^^^^^^^^^
  File "/home/airflow/.local/lib/python3.12/site-packages/airflow/models/taskinstance.py", line 733, in _execute_callable
    return ExecutionCallableRunner(
           ^^^^^^^^^^^^^^^^^^^^^^^^
  File "/home/airflow/.local/lib/python3.12/site-packages/airflow/utils/operator_helpers.py", line 252, in run
    return self.func(*args, **kwargs)
           ^^^^^^^^^^^^^^^^^^^^^^^^^^
  File "/home/airflow/.local/lib/python3.12/site-packages/airflow/models/baseoperator.py", line 406, in wrapper
    return func(self, *args, **kwargs)
           ^^^^^^^^^^^^^^^^^^^^^^^^^^^
  File "/home/airflow/.local/lib/python3.12/site-packages/airflow/operators/python.py", line 238, in execute
    return_value = self.execute_callable()
                   ^^^^^^^^^^^^^^^^^^^^^^^
  File "/home/airflow/.local/lib/python3.12/site-packages/airflow/operators/python.py", line 256, in execute_callable
    return runner.run(*self.op_args, **self.op_kwargs)
           ^^^^^^^^^^^^^^^^^^^^^^^^^^^^^^^^^^^^^^^^^^^
  File "/home/airflow/.local/lib/python3.12/site-packages/airflow/utils/operator_helpers.py", line 252, in run
    return self.func(*args, **kwargs)
           ^^^^^^^^^^^^^^^^^^^^^^^^^^
  File "/opt/airflow/dags/API_Crypto_Extraction.py", line 46, in cargar_data_a_base
    print(f"df final es {df_final.columns()}")
                         ^^^^^^^^^^^^^^^^^^
TypeError: 'Index' object is not callable
[2024-09-17T23:26:16.110+0000] {local_task_job_runner.py:266} INFO - Task exited with return code 1
[2024-09-17T23:26:16.130+0000] {taskinstance.py:3900} INFO - 0 downstream tasks scheduled from follow-on schedule check
[2024-09-17T23:26:16.133+0000] {local_task_job_runner.py:245} INFO - ::endgroup::
