[2024-09-17T23:46:27.288+0000] {local_task_job_runner.py:123} INFO - ::group::Pre task execution logs
[2024-09-17T23:46:27.484+0000] {taskinstance.py:2612} INFO - Dependencies all met for dep_context=non-requeueable deps ti=<TaskInstance: Bitcoin_ETL.extraer_data manual__2024-09-17T23:26:12.897497+00:00 [queued]>
[2024-09-17T23:46:27.496+0000] {taskinstance.py:2612} INFO - Dependencies all met for dep_context=requeueable deps ti=<TaskInstance: Bitcoin_ETL.extraer_data manual__2024-09-17T23:26:12.897497+00:00 [queued]>
[2024-09-17T23:46:27.497+0000] {taskinstance.py:2865} INFO - Starting attempt 5 of 6
[2024-09-17T23:46:27.516+0000] {taskinstance.py:2888} INFO - Executing <Task(PythonOperator): extraer_data> on 2024-09-17 23:26:12.897497+00:00
[2024-09-17T23:46:27.524+0000] {warnings.py:112} WARNING - /home/***/.local/lib/python3.12/site-packages/***/task/task_runner/standard_task_runner.py:70: DeprecationWarning: This process (pid=163) is multi-threaded, use of fork() may lead to deadlocks in the child.
  pid = os.fork()

[2024-09-17T23:46:27.527+0000] {standard_task_runner.py:72} INFO - Started process 172 to run task
[2024-09-17T23:46:27.525+0000] {standard_task_runner.py:104} INFO - Running: ['***', 'tasks', 'run', 'Bitcoin_ETL', 'extraer_data', 'manual__2024-09-17T23:26:12.897497+00:00', '--job-id', '70', '--raw', '--subdir', 'DAGS_FOLDER/API_Crypto_Extraction.py', '--cfg-path', '/tmp/tmpy0lg4x7k']
[2024-09-17T23:46:27.528+0000] {standard_task_runner.py:105} INFO - Job 70: Subtask extraer_data
[2024-09-17T23:46:27.579+0000] {task_command.py:467} INFO - Running <TaskInstance: Bitcoin_ETL.extraer_data manual__2024-09-17T23:26:12.897497+00:00 [running]> on host 2da82ea3b7fd
[2024-09-17T23:46:27.675+0000] {taskinstance.py:3131} INFO - Exporting env vars: AIRFLOW_CTX_DAG_OWNER='NicolasRivas' AIRFLOW_CTX_DAG_ID='Bitcoin_ETL' AIRFLOW_CTX_TASK_ID='extraer_data' AIRFLOW_CTX_EXECUTION_DATE='2024-09-17T23:26:12.897497+00:00' AIRFLOW_CTX_TRY_NUMBER='5' AIRFLOW_CTX_DAG_RUN_ID='manual__2024-09-17T23:26:12.897497+00:00'
[2024-09-17T23:46:27.676+0000] {taskinstance.py:731} INFO - ::endgroup::
[2024-09-17T23:46:28.909+0000] {logging_mixin.py:190} INFO - df final es Index(['id', 'name', 'priceUsd', 'date_time', 'key_id_date_time'], dtype='object')
[2024-09-17T23:46:28.912+0000] {logging_mixin.py:190} INFO - El host es None
[2024-09-17T23:46:28.912+0000] {logging_mixin.py:190} INFO - La base es None
[2024-09-17T23:46:28.913+0000] {logging_mixin.py:190} INFO - El user es None
[2024-09-17T23:46:28.913+0000] {logging_mixin.py:190} INFO - La pas es None
[2024-09-17T23:46:28.914+0000] {taskinstance.py:3310} ERROR - Task failed with exception
Traceback (most recent call last):
  File "/home/airflow/.local/lib/python3.12/site-packages/airflow/models/taskinstance.py", line 767, in _execute_task
    result = _execute_callable(context=context, **execute_callable_kwargs)
             ^^^^^^^^^^^^^^^^^^^^^^^^^^^^^^^^^^^^^^^^^^^^^^^^^^^^^^^^^^^^^
  File "/home/airflow/.local/lib/python3.12/site-packages/airflow/models/taskinstance.py", line 733, in _execute_callable
    return ExecutionCallableRunner(
           ^^^^^^^^^^^^^^^^^^^^^^^^
  File "/home/airflow/.local/lib/python3.12/site-packages/airflow/utils/operator_helpers.py", line 252, in run
    return self.func(*args, **kwargs)
           ^^^^^^^^^^^^^^^^^^^^^^^^^^
  File "/home/airflow/.local/lib/python3.12/site-packages/airflow/models/baseoperator.py", line 406, in wrapper
    return func(self, *args, **kwargs)
           ^^^^^^^^^^^^^^^^^^^^^^^^^^^
  File "/home/airflow/.local/lib/python3.12/site-packages/airflow/operators/python.py", line 238, in execute
    return_value = self.execute_callable()
                   ^^^^^^^^^^^^^^^^^^^^^^^
  File "/home/airflow/.local/lib/python3.12/site-packages/airflow/operators/python.py", line 256, in execute_callable
    return runner.run(*self.op_args, **self.op_kwargs)
           ^^^^^^^^^^^^^^^^^^^^^^^^^^^^^^^^^^^^^^^^^^^
  File "/home/airflow/.local/lib/python3.12/site-packages/airflow/utils/operator_helpers.py", line 252, in run
    return self.func(*args, **kwargs)
           ^^^^^^^^^^^^^^^^^^^^^^^^^^
  File "/opt/airflow/dags/API_Crypto_Extraction.py", line 60, in cargar_data_a_base
    conn = psycopg2.connect(
           ^^^^^^^^^^^^^^^^^
  File "/home/airflow/.local/lib/python3.12/site-packages/psycopg2/__init__.py", line 122, in connect
    conn = _connect(dsn, connection_factory=connection_factory, **kwasync)
           ^^^^^^^^^^^^^^^^^^^^^^^^^^^^^^^^^^^^^^^^^^^^^^^^^^^^^^^^^^^^^^^
psycopg2.OperationalError: connection to server on socket "/var/run/postgresql/.s.PGSQL.5439" failed: No such file or directory
	Is the server running locally and accepting connections on that socket?

[2024-09-17T23:46:28.932+0000] {taskinstance.py:1225} INFO - Marking task as UP_FOR_RETRY. dag_id=Bitcoin_ETL, task_id=extraer_data, run_id=manual__2024-09-17T23:26:12.897497+00:00, execution_date=20240917T232612, start_date=20240917T234627, end_date=20240917T234628
[2024-09-17T23:46:28.955+0000] {taskinstance.py:340} INFO - ::group::Post task execution logs
[2024-09-17T23:46:28.956+0000] {standard_task_runner.py:124} ERROR - Failed to execute job 70 for task extraer_data (connection to server on socket "/var/run/postgresql/.s.PGSQL.5439" failed: No such file or directory
	Is the server running locally and accepting connections on that socket?
; 172)
Traceback (most recent call last):
  File "/home/airflow/.local/lib/python3.12/site-packages/airflow/task/task_runner/standard_task_runner.py", line 117, in _start_by_fork
    ret = args.func(args, dag=self.dag)
          ^^^^^^^^^^^^^^^^^^^^^^^^^^^^^
  File "/home/airflow/.local/lib/python3.12/site-packages/airflow/cli/cli_config.py", line 49, in command
    return func(*args, **kwargs)
           ^^^^^^^^^^^^^^^^^^^^^
  File "/home/airflow/.local/lib/python3.12/site-packages/airflow/utils/cli.py", line 115, in wrapper
    return f(*args, **kwargs)
           ^^^^^^^^^^^^^^^^^^
  File "/home/airflow/.local/lib/python3.12/site-packages/airflow/cli/commands/task_command.py", line 483, in task_run
    task_return_code = _run_task_by_selected_method(args, _dag, ti)
                       ^^^^^^^^^^^^^^^^^^^^^^^^^^^^^^^^^^^^^^^^^^^^
  File "/home/airflow/.local/lib/python3.12/site-packages/airflow/cli/commands/task_command.py", line 256, in _run_task_by_selected_method
    return _run_raw_task(args, ti)
           ^^^^^^^^^^^^^^^^^^^^^^^
  File "/home/airflow/.local/lib/python3.12/site-packages/airflow/cli/commands/task_command.py", line 341, in _run_raw_task
    return ti._run_raw_task(
           ^^^^^^^^^^^^^^^^^
  File "/home/airflow/.local/lib/python3.12/site-packages/airflow/utils/session.py", line 97, in wrapper
    return func(*args, session=session, **kwargs)
           ^^^^^^^^^^^^^^^^^^^^^^^^^^^^^^^^^^^^^^
  File "/home/airflow/.local/lib/python3.12/site-packages/airflow/models/taskinstance.py", line 3004, in _run_raw_task
    return _run_raw_task(
           ^^^^^^^^^^^^^^
  File "/home/airflow/.local/lib/python3.12/site-packages/airflow/models/taskinstance.py", line 273, in _run_raw_task
    TaskInstance._execute_task_with_callbacks(
  File "/home/airflow/.local/lib/python3.12/site-packages/airflow/models/taskinstance.py", line 3158, in _execute_task_with_callbacks
    result = self._execute_task(context, task_orig)
             ^^^^^^^^^^^^^^^^^^^^^^^^^^^^^^^^^^^^^^
  File "/home/airflow/.local/lib/python3.12/site-packages/airflow/models/taskinstance.py", line 3182, in _execute_task
    return _execute_task(self, context, task_orig)
           ^^^^^^^^^^^^^^^^^^^^^^^^^^^^^^^^^^^^^^^
  File "/home/airflow/.local/lib/python3.12/site-packages/airflow/models/taskinstance.py", line 767, in _execute_task
    result = _execute_callable(context=context, **execute_callable_kwargs)
             ^^^^^^^^^^^^^^^^^^^^^^^^^^^^^^^^^^^^^^^^^^^^^^^^^^^^^^^^^^^^^
  File "/home/airflow/.local/lib/python3.12/site-packages/airflow/models/taskinstance.py", line 733, in _execute_callable
    return ExecutionCallableRunner(
           ^^^^^^^^^^^^^^^^^^^^^^^^
  File "/home/airflow/.local/lib/python3.12/site-packages/airflow/utils/operator_helpers.py", line 252, in run
    return self.func(*args, **kwargs)
           ^^^^^^^^^^^^^^^^^^^^^^^^^^
  File "/home/airflow/.local/lib/python3.12/site-packages/airflow/models/baseoperator.py", line 406, in wrapper
    return func(self, *args, **kwargs)
           ^^^^^^^^^^^^^^^^^^^^^^^^^^^
  File "/home/airflow/.local/lib/python3.12/site-packages/airflow/operators/python.py", line 238, in execute
    return_value = self.execute_callable()
                   ^^^^^^^^^^^^^^^^^^^^^^^
  File "/home/airflow/.local/lib/python3.12/site-packages/airflow/operators/python.py", line 256, in execute_callable
    return runner.run(*self.op_args, **self.op_kwargs)
           ^^^^^^^^^^^^^^^^^^^^^^^^^^^^^^^^^^^^^^^^^^^
  File "/home/airflow/.local/lib/python3.12/site-packages/airflow/utils/operator_helpers.py", line 252, in run
    return self.func(*args, **kwargs)
           ^^^^^^^^^^^^^^^^^^^^^^^^^^
  File "/opt/airflow/dags/API_Crypto_Extraction.py", line 60, in cargar_data_a_base
    conn = psycopg2.connect(
           ^^^^^^^^^^^^^^^^^
  File "/home/airflow/.local/lib/python3.12/site-packages/psycopg2/__init__.py", line 122, in connect
    conn = _connect(dsn, connection_factory=connection_factory, **kwasync)
           ^^^^^^^^^^^^^^^^^^^^^^^^^^^^^^^^^^^^^^^^^^^^^^^^^^^^^^^^^^^^^^^
psycopg2.OperationalError: connection to server on socket "/var/run/postgresql/.s.PGSQL.5439" failed: No such file or directory
	Is the server running locally and accepting connections on that socket?

[2024-09-17T23:46:28.987+0000] {local_task_job_runner.py:266} INFO - Task exited with return code 1
[2024-09-17T23:46:29.004+0000] {taskinstance.py:3900} INFO - 0 downstream tasks scheduled from follow-on schedule check
[2024-09-17T23:46:29.006+0000] {local_task_job_runner.py:245} INFO - ::endgroup::
